<?xml version="1.0"?>
<!--sdf version='1.4'>
  <model name="a_robot">
  </model>
</sdf-->
<robot name="ClubBotII">

  <material name="red">
    <color rgba="1 0 0 1"/>
  </material>

  <material name="green">
    <color rgba="0 1 0 1"/>
  </material>

  <material name="blue">
    <color rgba="0 0 1 1"/>
  </material>

  <material name="white">
    <color rgba="1 1 1 1"/>
  </material>

  <material name="black">
    <color rgba="0 0 0 1"/>
  </material>

  <link name="base_link">
    <visual>
      <geometry>
        <mesh filename="package://clubbot_description/meshes/Base_link.stl" scale="0.001 0.001 0.001"/>
      </geometry>
      <origin rpy="0 0 0" xyz="0.0 0.0 0.0"/>
      <material name="white"/>
    </visual>
    <collision>
      <geometry>
        <box size="0.23 0.24 0.12"/>
      </geometry>
    </collision>
    <!--inertia still pertains to terence = cylinder-->
    <inertial>
      <mass value="1.71"/>
      <inertia ixx="0.007" ixy="0.0" ixz="0.0" iyy="0.007" iyz="0.0" izz="0.013"/>
    </inertial>
  </link>

  <link name="left_wheel">
    <visual>
      <geometry>
        <mesh filename="package://clubbot_description/meshes/SpikeyWheel.stl" scale="0.001 0.001 0.001"/>
        <!--cylinder length="0.04" radius="0.04"/-->
      </geometry>
      <origin rpy="0 0 0" xyz="0.0 0.0 0.0"/>
      <material name="black"/>
    </visual>
    <collision>
      <geometry>
        <cylinder length="0.04" radius="0.04"/>
      </geometry>
    </collision>
    <inertial>
      <mass value="0.055"/>
      <inertia ixx="0.00003" ixy="0.0" ixz="0.0" iyy="0.00003" iyz="0.0" izz="0.0004"/>
    </inertial>
  </link>

  <joint name="left_wheel_to_base_link" type="continuous">
    <axis xyz="0 0 1"/>
    <parent link="base_link"/>
    <child link="left_wheel"/>
    <origin rpy="0 1.5708 0" xyz="0.09 0.01 -0.05"/>
  </joint>

    <link name="right_wheel">
    <visual>
      <geometry>
        <mesh filename="package://clubbot_description/meshes/SpikeyWheel.stl" scale="0.001 0.001 0.001"/>
        <!--cylinder length="0.04" radius="0.04"/-->
      </geometry>
      <origin rpy="0 0 0" xyz="0.0 0.0 0.0"/>
      <material name="black"/>
    </visual>
    <collision>
      <geometry>
        <cylinder length="0.04" radius="0.04"/>
      </geometry>
    </collision>
    <inertial>
      <mass value="0.055"/>
      <inertia ixx="0.00003" ixy="0.0" ixz="0.0" iyy="0.00003" iyz="0.0" izz="0.0004"/>
    </inertial>
  </link>

  <joint name="right_wheel_to_base_link" type="continuous">
    <axis xyz="0 0 1"/>
    <parent link="base_link"/>
    <child link="right_wheel"/>
    <origin rpy="0 -1.5708 0" xyz="-0.09 0.01 -0.05"/>
  </joint>

  <link name="top_usb_cam">
    <visual>
      <material name="green"/>
      <geometry>
        <mesh filename="package://clubbot_description/meshes/camera_top.stl" scale="0.001 0.001 0.001"/>"
      </geometry>
    </visual>
    <!-- Need to add collision and inertia for top-->
  </link>

  <joint name="top_to_base" type="fixed">
    <parent link="base_link"/>
    <child link="top_usb_cam"/>
    <origin rpy="0 0 0" xyz="-0.00 0.00 0.05"/>
  </joint>



</robot>